try {
    console.log(naoExisto)
} catch(err) {
    console.log(`Ocorreu um erro inesperado :(`)
    console.log(err)
}